<?xml version='1.0'?>
<!-- DEF: robot has core footprint, rectangular chassis, left and right wheels, and front and back casters.    -->
<!--       all six objects have appearances and are connected through joints, creating the entire robot frame. -->
<robot name="my_robot" xmlns:xacro="http://www.ros.org/wiki/xacro">
  <!-- include below will add gazebo file that defines three necessary plug-ins for actuators, camera and lidar -->
  <xacro:include filename="$(find my_robot)/urdf/my_robot.gazebo" />
  
  <link name="robot_footprint" />
  
  <joint name="robot_footprint_joint" type="fixed">
    <origin xyz="0 0 0" rpy="0 0 0" />
    <parent link="robot_footprint" />
    <child link="chassis" />
  </joint>
  
  <!-- central chassis (with casters included) link -->
  <link name="chassis">
    <pose>0 0 0.1 0 0 0</pose>
    
    <inertial>
      <mass value="15.0" />
      <origin xyz="0.0 0 0" rpy="0 0 0" />
      <inertia
        ixx="0.1" ixy="0" ixz="0"
        iyy="0.1" iyz="0"
        izz="0.1"
      />
    </inertial>
      
    <!-- main body appearance defintion -->
    <collision name="chassis_collision">
      <origin xyz="0 0 0" rpy="0 0 0" />
      <geometry>
        <box size=".48 .24 .12" />
      </geometry>
    </collision>
      
    <visual name="chassis_visual">
      <origin xyz="0 0 0" rpy="0 0 0" />
      <geometry>
        <box size=".48 .24 .12" />
      </geometry>
    </visual>
    
    <!-- back caster appearance definition -->
    <collision name='back_caster_collision'>
      <origin xyz="-0.18 0 -0.06" rpy="0 0 0" />
      <geometry>
        <sphere radius="0.0599" />
      </geometry>
    </collision>

    <visual name='back_caster_visual'>
      <origin xyz="-0.18 0 -0.06" rpy="0 0 0" />
      <geometry>
        <sphere radius="0.06" />
      </geometry>
    </visual>

    <!-- front caster appearance definition -->
    <collision name='front_caster_collision'>
      <origin xyz="0.18 0 -0.06" rpy="0 0 0" />
      <geometry>
        <sphere radius="0.0599" />
      </geometry>
    </collision>

    <visual name='front_caster_visual'>
      <origin xyz="0.18 0 -0.06" rpy="0 0 0" />
      <geometry>
        <sphere radius="0.06" />
      </geometry>
    </visual>
  </link>
  
  <gazebo reference="chassis">
    <material>Gazebo/SkyBlue</material>
  </gazebo>
  
  <!-- left continuous wheel definition -->
  <link name="left_wheel">
    <inertial>
      <mass value="5.0" />
      <origin xyz="0 0 0" rpy="0 1.5707 1.5707" />
      <inertia
        ixx="0.1" ixy="0" ixz="0"
        iyy="0.1" iyz="0"
        izz="0.1"
      />
    </inertial>
    
    <collision name="left_wheel_collision">
      <origin xyz="0 0 0" rpy="0 1.5707 1.5707" />
      <geometry>
        <cylinder radius="0.12" length="0.06" />
      </geometry>
    </collision>
    
    <visual name="left_wheel_visual">
      <origin xyz="0 0 0" rpy="0 1.5707 1.5707" />
      <geometry>
        <cylinder radius="0.12" length="0.06" />
      </geometry>
    </visual>                                                                         
  </link>
  
  <gazebo reference="left_wheel">
    <material>Gazebo/Black</material>
  </gazebo>
  
  <!-- right continuous wheel definition -->
  <link name="right_wheel">
    <inertial>
      <mass value="5.0" />
      <origin xyz="0 0 0" rpy="0 1.5707 1.5707" />
      <inertia
        ixx="0.1" ixy="0" ixz="0"
        iyy="0.1" iyz="0"
        izz="0.1"
      />
    </inertial>
    
    <collision name="right_wheel_collision">
      <origin xyz="0 0 0" rpy="0 1.5707 1.5707" />
      <geometry>
        <cylinder radius="0.12" length="0.06" />
      </geometry>
    </collision>
    
    <visual name="right_wheel_visual">
      <origin xyz="0 0 0" rpy="0 1.5707 1.5707" />
      <geometry>
        <cylinder radius="0.12" length="0.06" />
      </geometry>
    </visual>                                                                         
  </link>
  
  <gazebo reference="right_wheel">
    <material>Gazebo/Black</material>
  </gazebo>
    
  <!-- left wheel joint (connected to chassis) -->
  <joint type="continuous" name="left_wheel_hinge">
    <origin xyz="0 0.18 0" rpy="0 0 0" />
    <child link="left_wheel" />
    <parent link="chassis" />
    <axis xyz="0 1 0" rpy="0 0 0" />
    <limit effort="10000" velocity="1000" />
    <dynamics damping="1.0" friction="1.0" />
  </joint>
  
  <!-- right wheel joint (connected to chassis) -->
  <joint type="continuous" name="right_wheel_hinge">
    <origin xyz="0 -0.18 0" rpy="0 0 0" />
    <child link="right_wheel" />
    <parent link="chassis" />
    <axis xyz="0 1 0" rpy="0 0 0" />
    <limit effort="10000" velocity="1000" />
    <dynamics damping="1.0" friction="1.0" />
  </joint>
  
  <!-- camera sensor definition  -->
  <link name="camera">
    <box_inertia x="0.05" y="0.05" z="0.05" m="0.1" />
  
    <inertial>
      <mass value="0.1" />
      <origin xyz="0 0 0" rpy="0 0 0" />
      <inertia
         ixx="1e-6" ixy="0" ixz="0"
         iyy="1e-6" iyz="0"
         izz="1e-6"
      />
    </inertial>
    
    <collision name="camera_collision">
      <origin xyz="0 0 0" rpy="0 0 0" />
      <geometry>
        <box size="0.05 0.05 0.05" />
      </geometry>
    </collision>
    
    <visual name="camera_visual">
      <origin xyz="0 0 0" rpy="0 0 0" />
      <geometry>
        <box size="0.05 0.05 0.05" />
      </geometry>
    </visual>
  </link>
  
  <gazebo reference="camera">
    <material>Gazebo/Red</material>
  </gazebo>
  
  <!-- camera joint definition -->
  <joint type="fixed" name="camera_joint">
    <origin xyz="0.24 0 0" rpy="0 0 0" />
    <child link="camera" />
    <parent link="chassis" />
    <axis xyz="0 1 0" rpy="0 0 0" />
  </joint>
  
  <!-- lidar sensor definition -->
  <link name="hokuyo">
    <inertial>
      <mass value="1e-5" />
      <origin xyz="0 0 0" rpy="0 0 0" />
      <inertia
         ixx="1e-6" ixy="0" ixz="0"
         iyy="1e-6" iyz="0"
         izz="1e-6"
      />
    </inertial>
    
    <collision name="hokuyo_collision">
      <origin xyz="0 0 0" rpy="0 0 0" />
      <geometry>
        <box size="0.1 0.1 0.1" />
      </geometry>
    </collision>
    
    <visual name="hokuyo_visual">
      <origin xyz="0 0 0" rpy="0 0 0" />
      <geometry>
        <mesh filename="package://my_robot/meshes/hokuyo.dae" />
      </geometry>
    </visual>
  </link>
  
  <!-- lidar joint definition -->
  <joint type="fixed" name="hokuyo_joint">
    <origin xyz="0.16 0 0.12" rpy="0 0 0" />
    <child link="hokuyo" />
    <parent link="chassis" />
    <axis xyz="0 1 0" rpy="0 0 0" />
  </joint>
</robot>
